{"Error Text":"AttributeError 'SAM' object has no attribute 'features'","Alignment":"This error indicates that an attempt was made to access the features attribute on an instance of a SAM object, which does not exist"}
{"Error Text":"ValueError Failed to find data adapter that can handle input","Alignment":"This error occurs when TensorFlow or Keras cannot find a suitable data adapter for the provided input format during model training or evaluation, indicating that the input data is not in a supported format or shape; ensure the input data is correctly formatted as a Numpy array, TensorFlow tensor, or a supported dataset type."}
{"Error Text":"AttributeError 'list' object has no attribute 'cuda'","Alignment":"This error occurs when attempting to call the `.cuda()` method on a Python list object in PyTorch, implying that the operation meant to move data to a CUDA device is applicable to PyTorch tensors, not lists; convert the list to a tensor before applying CUDA operations."}
{"Error Text":"ValueError The following argument(s) are not supported with the native Keras format: ['options']","Alignment":"This error occurs when attempting to use an argument, specifically `options`, that is not recognized or supported by the native Keras model methods or functions, suggesting either a typo, a misuse of API, or the need to remove or replace the unsupported argument with a valid one according to the Keras documentation."}
{"Error Text":"OSError Bad file descriptor","Alignment":"This error occurs when an operation attempts to use an invalid file descriptor, which might have been closed or never correctly opened, indicating a need to ensure that file operations are performed on valid, open file descriptors."}
{"Error Text":"AttributeError module 'gpuinfo' has no attribute 'gpu_usage'","Alignment":"This error occurs when attempting to access an attribute `gpu_usage` that does not exist in the `gpuinfo` module, indicating either a typo, the use of an outdated or incorrect version of the module, or that the desired functionality must be sought in a different function or module."}
{"Error Text":"ValueError slice index 1 of dimension 1 out of bounds. for '{{node strided_slice_1}} = StridedSlice[Index=DT_INT32, T=DT_FLOAT, begin_mask=0, ellipsis_mask=1, end_mask=0, new_axis_mask=4, shrink_axis_mask=2](IteratorGetNext:1, strided_slice_1\/stack, strided_slice_1\/stack_1, strided_slice_1\/stack_2)' with input shapes: [?,1], [3], [3], [3] and with computed input tensors: input[1] = <0 1 0>, input[2] = <0 2 0>, input[3] = <1 1 1>.","Alignment":"This error occurs when attempting to slice a tensor with a dimension index that exceeds the tensor's shape limits, specifically when the second dimension (dimension 1) is accessed with an index out of its range,"}
{"Error Text":"OSError Please specify a non-directory filepath for ModelCheckpoint. Filepath used is an existing directory:","Alignment":"This error occurs when the `ModelCheckpoint` callback in Keras expects a file path for saving a model, but a directory path is provided instead; specify a file path including the filename."}
{"Error Text":"cv2.error OpenCV(4.8.0) :-1: error: (-5:Bad argument) in function 'imwrite'\n> Overload resolution failed:\n>  - img data type = 0 is not supported\n>  - Expected Ptr<cv::UMat> for argument 'img'","Alignment":"The error occurs because the data type of the image (`img`) is unsupported or incompatible, expected data type is a `cv::UMat` pointer."}
{"Error Text":"AttributeError 'numpy.ndarray' object has no attribute 'numpy'","Alignment":"This error occurs when attempting to access the `numpy` attribute of a NumPy array, which doesn't exist; likely caused by mistakenly calling `numpy` on an already existing NumPy array, which isn't needed."}
{"Error Text":"ValueError operands could not be broadcast together with shapes (11,11) (11,11,3) ","Alignment":"This error arises when attempting to broadcast arrays with incompatible shapes, typically due to mismatched dimensions; rectify it by ensuring that the shapes of the arrays being broadcasted are compatible or by explicitly reshaping them."}
{"Error Text":"ValueError Shapes (32, 10) and (32, 13, 13, 10) are incompatible","Alignment":"This error occurs because the shapes of the arrays (32, 10) and (32, 13, 13, 10) are incompatible for broadcasting, likely due to a mismatch in dimensions; resolve it by ensuring consistent dimensions or reshaping the arrays accordingly."}
{"Error Text":"ValueError can only convert an array of size 1 to a Python scalar","Alignment":"This error happens when trying to convert an array with a size greater than 1 into a scalar, commonly caused by mistakenly treating an array as a scalar; to fix, ensure the operation is compatible with array inputs."}
{"Error Text":"ValueError text input must be of type `str` (single example), `List[str]` (batch or single pretokenized example) or `List[List[str]]` (batch of pretokenized examples)","Alignment":"This error occurs when the input provided to a text-related function is not in the expected format, namely a string, a list of strings, or a list of lists of strings; ensure the input is correctly formatted to match the function's requirements."}
{"Error Text":"cv2.error DatasetV2.map() got an unexpected keyword argument 'batched'","Alignment":"This error arises when the `map()` method of a DatasetV2 object is called with an unexpected keyword argument 'batched', likely due to an incorrect method signature or version mismatch; ensure compatibility by checking the method's documentation or updating dependencies if necessary."}
{"Error Text":"ValueError Unexpected result of `train_function` (Empty logs). Please use `Model.compile(..., run_eagerly=True)`, or `tf.config.run_functions_eagerly(True)` for more information of where went wrong, or file a issue\/bug to `tf.keras`","Alignment":"This error occurs when the training function produces empty logs unexpectedly, suggesting a possible issue with the model setup or data processing; try using `Model.compile(..., run_eagerly=True)` or `tf.config.run_functions_eagerly(True)` for more details on the problem."}
{"Error Text":"RuntimeError Parent directory .\/model_checkpoint\/fine_tuned_sam does not exist","Alignment":"This error arises because the parent directory \".\/model_checkpoint\/fine_tuned_sam\" does not exist, typically caused by a misconfiguration or missing directory creation step; rectify it by ensuring the parent directory exists or create it before attempting to access it."}
{"Error Text":"TypeError Singleton array array(<BatchDataset element_spec=(TensorSpec(shape=(None, 11, 11, 3), dtype=tf.float32, name=None), TensorSpec(shape=(None, 2), dtype=tf.float32, name=None))>,\n      dtype=object) cannot be considered a valid collection.","Alignment":"This error occurs when trying to treat a singleton array, specifically a BatchDataset object, as a valid collection, which it isn't; likely caused by attempting to iterate over or perform operations expecting a collection on a single dataset instance, handle it appropriately as a single dataset object."}
{"Error Text":"ValueError Exception encountered when calling layer \"model\" (type Functional)\n    \n    Input 0 of layer \"conv1\" is incompatible with the layer: expected axis -1 of input shape to have value 3, but received input with shape (None, 11, 11, 1)\n    \n    Call arguments received:\n      \u2022 inputs=tf.Tensor(shape=(None, 11, 11, 1), dtype=float32)\n      \u2022 training=True\n      \u2022 mask=None","Alignment":"This error arises because the input shape received by the layer \"conv1\" doesn't match its expectations, expecting the last axis to have a size of 3 but receiving an input shape of (None, 11, 11, 1); ensure the input has the correct number of channels (3 in this case) or adjust the layer's configuration accordingly."}
{"Error Text":"PermissionError Permission denied: '\/data\/'","Alignment":"This error occurs when attempting to access a directory or file for which the user does not have the necessary permissions, typically caused by trying to read or write to a directory without appropriate access rights; rectify it by granting the necessary permissions to the user or adjusting the file access permissions accordingly."}
{"Error Text":"AttributeError 'Model' object has no attribute 'add'","Alignment":"This error occurs when trying to use the `add` method on a `Model` object, which does not have this attribute; instead, use the appropriate method to add layers to the model, such as `Sequential`'s `add` method or functional API's layer instantiation and connection."}
{"Error Text":"ValueError Error when checking target: expected dense_2 to have shape (128,) but got array with shape (3,)","Alignment":"This error arises because the target data has a shape of (3,) which doesn't match the expected shape (128,) for the output layer \"dense_2\""}
{"Error Text":"RuntimeError You must compile a model before training\/testing. Use `model.compile(optimizer, loss)`","Alignment":"This error occurs when attempting to train or test a model without compiling it first; resolve it by calling the `compile` method on the model instance with appropriate optimizer and loss function parameters before training or testing."}
{"Error Text":"[Errno 116] Stale file handle","Alignment":"This error  usually indicates that a file handle, which was previously valid, is no longer valid. This can happen due to various reasons, such as the file being deleted or the file system experiencing corruption."}
{"Error Text":"ValueError You are trying to load a weight file containing 12 layers into a model with 11 layers","Alignment":"ValueError You are trying to load a weight file containing 12 layers into a model with 11 layers"}
{"Error Text":"ValueError All arrays must be of the same length","Alignment":"ValueError All arrays must be of the same length"}
{"Error Text":" RuntimeError Error(s) in loading state_dict for Sam:\n\tMissing key(s) in state_dict: \"image_encoder.patch_embed.seq.0.c.weight\", \"image_encoder.patch_embed.seq.0.bn.weight\"","Alignment":"This error occurs because certain keys are missing in the state dictionary when loading the model's state_dict for Sam. Specifically, \"image_encoder.patch_embed.seq.0.c.weight\" and \"image_encoder.patch_embed.seq.0.bn.weight\" are missing. This could be due to differences in model architectures or the state_dict being incomplete or corrupted."}
{"Error Text":"RuntimeError size mismatch for image_encoder.neck.0.weight: copying a param with shape torch.Size([256, 768, 1, 1]) from checkpoint, the shape in current model is torch.Size([256, 320, 1, 1])","Alignment":"RuntimeError size mismatch for image_encoder.neck.0.weight: copying a param with shape torch.Size([256, 768, 1, 1]) from checkpoint, the shape in current model is torch.Size([256, 320, 1, 1])"}
{"Error Text":"ValueError cannot reshape array of size 10629 into shape (512,512,1)","Alignment":"The error occurs because the total number of elements in the array (10629) does not match the specified shape (512x512x1), indicating an incompatible reshape operation, often caused by incorrect dimensions or inconsistent data structures."}
{"Error Text":"AttributeError module 'numpy' has no attribute 'unit8'","Alignment":"The error is due to a misspelling of the data type \"uint8\" as \"unit8\", causing an AttributeError since the correct attribute is not found within the numpy module."}
{"Error Text":"pynvml.nvml.NVMLError Uninitialized: Uninitialized","Alignment":"The error \"Uninitialized: Uninitialized\" in pynvml.nvml.NVMLError typically indicates an attempt to access GPU information without initializing the NVML library first, commonly resolved by initializing NVML before accessing GPU data."}
{"Error Text":"IndexError index 0 is out of bounds for axis 0 with size 0","Alignment":"The error suggests an attempt to access the first element of an empty array (size 0 along axis 0), commonly arising from empty data structures, necessitating a check to ensure non-empty arrays before accessing elements."}
{"Error Text":"ValueError  Layer \"model\" expects 1 input(s), but it received 969 input tensors. Inputs received: [<tf.Tensor 'IteratorGetNext:0' shape=(None, 11, 3) dtype=uint8>, <tf.Tensor 'IteratorGetNext:1' shape=(None, 11, 3) dtype=uint8>,\u2026","Alignment":"The error indicates a mismatch between the expected number of input tensors (1) and the actual number received (969), typically due to incorrect input dimensions or data formatting in the neural network model."}
{"Error Text":"RuntimeError Sizes of tensors must match except in dimension 1. Expected size 2 but got size 1 for tensor number 499 in the list.","Alignment":"The error suggests a dimension mismatch in a tensor list, indicating that all dimensions except the first must match, often resolved by ensuring consistent tensor sizes across the list except for dimension 1."}
{"Error Text":"AttributeError 'str' object has no attribute 'keys'","Alignment":"This error occurs when trying to access the keys of a string in Python, which isn't possible because strings do not have a 'keys' attribute; use a dictionary instead to access keys."}
{"Error Text":"TypeError type numpy.ndarray doesn't define __round__ method","Alignment":"The error indicates that you're trying to round a NumPy array directly, which isn't supported; you need to apply the round function to the array elements individually."}
{"Error Text":"TypeError can only concatenate str (not \"datetime.datetime\") to str","Alignment":"This error arises when attempting to concatenate a string with a datetime object directly in Python; convert the datetime object to a string using a suitable format method before concatenating."}
{"Error Text":"KeyError 'val_loss'","Alignment":"This error suggests that the key \"val_loss\" does not exist in the dictionary; ensure the key is spelled correctly and exists in the dictionary before attempting to access it."}
{"Error Text":"AttributeError 'NoneType' object has no attribute 'shape'","Alignment":"This error indicates that you're trying to access the 'shape' attribute of a NoneType object, commonly occurring when attempting operations on a variable that is None; ensure the variable is assigned a valid value before accessing its attributes."}
{"Error Text":"AttributeError 'list' object has no attribute 'cuda'","Alignment":"This error occurs when trying to perform CUDA operations on a list object in PyTorch, which isn't possible; ensure you're working with tensors instead of lists for CUDA operations."}
{"Error Text":"TypeError can only concatenate str (not \"Adam\") to str","Alignment":"This error occurs when trying to concatenate a string with a non-string object, such as \"Adam\"; ensure both operands are strings or convert the non-string object to a string before concatenation."}
{"Error Text":"TypeError Could not build a `TypeSpec` for [array([[[ 0,  0,  0],\n        [ 0,  0,  0],\n        [ 0,  0,  0],\n        [ 0,  0,  0],\n        [ 0,  0,  0],\n        [ 0,  0,  0],\n        [ 0,  1,  0],\n        [ 1,  1,  0],\n        [ 3,  1,  0],\n        [ 5,  1,  0],\n        [ 6,  1,  0]],....","Alignment":"This error typically occurs in TensorFlow when trying to build a `TypeSpec` for a complex data structure like a NumPy array; ensure that the data structure is compatible with TensorFlow operations or convert it to a compatible format."}
{"Error Text":"csv.Error iterable expected, not numpy.float64","Alignment":"This error arises when attempting to write a NumPy float64 object directly to a CSV file; convert the NumPy float64 object to a Python built-in type, such as a Python float, before writing it to the CSV file."}
{"Error Text":"AttributeError module 'gradcam' has no attribute 'save_and_display_gradcam'","Alignment":"The AttributeError indicates that the 'gradcam' module does not have a save_and_display_gradcam attribute, which could be due to incorrect module installation, an outdated version, or using a function that doesn't exist in the library; ensure the correct library is installed and the function name is correctly spelled according to the documentation."}
{"Error Text":"RuntimeError mat1 and mat2 shapes cannot be multiplied (64x576 and 1600x100)","Alignment":"The RuntimeError occurs because the matrices mat1 and mat2 have incompatible shapes for multiplication, specifically, the number of columns in mat1 (576) does not match the number of rows in mat2 (1600); ensure that the dimensions of the matrices align appropriately for matrix multiplication"}
{"Error Text":"ValueError invalid literal for int() with base 10: '1.pth'","Alignment":"The `ValueError` occurs when attempting to convert the string '1.pth' to an integer using `int()`, which fails because '1.pth' contains non-numeric characters; verify and clean your input data to ensure only numeric strings are passed to the `int()` function."}
{"Error Text":"TypeError Expected state_dict to be dict-like, got <class 'segment_anything.modeling.sam.Sam'>.","Alignment":"The `TypeError` indicates that a non-dict-like object, specifically an instance of `segment_anything.modeling.sam.Sam`, was provided where a dictionary was expected, typically in a function expecting model parameters; ensure you are passing the `.state_dict()` of the model object, not the model object itself."}
{"Error Text":"AttributeError 'BatchDataset' object has no attribute 'shape'","Alignment":"The `AttributeError` suggests that the 'BatchDataset' object does not have a 'shape' attribute, which is typical for dataset objects in frameworks like TensorFlow; instead, use methods specific to dataset handling, such as examining individual elements or using dataset properties to understand structure and dimensions."}
{"Error Text":"TypeError BatchDataset' object is not subscriptable","Alignment":"The `TypeError` indicates that a 'BatchDataset' object does not support indexing directly, which is common for dataset objects in machine learning frameworks; instead, iterate through the dataset or use dataset-specific methods to access elements."}
{"Error Text":"IndexError index 59 is out of bounds for axis 3 with size 16","Alignment":"The `IndexError` indicates that you are attempting to access index 59 on axis 3 of an array or tensor, which only has a size of 16; ensure your indexing is within the actual bounds of the data structure by checking dimensions and adjusting indices accordingly."}
{"Error Text":"OSError Not found: \"\/weights\/LLaMA\/tokenizer.model\": No such file or directory Error #2","Alignment":"The `OSError` occurs because the file at \"\/weights\/LLaMA\/tokenizer.model\" cannot be found, likely due to an incorrect path or the file not being present at the specified location; verify the file path and ensure the file exists in the directory you are accessing."}
{"Error Text":"list indices must be integers or slices, not tuple","Alignment":"The error \"list indices must be integers or slices, not tuple\" occurs when trying to access elements of a list using a tuple as an index, which is not supported; ensure you use only integers or slice objects to index lists."}
{"Error Text":"ValueError No images found in directory \/train. Allowed formats: ('.bmp', '.gif', '.jpeg', '.jpg', '.png')","Alignment":"The `ValueError` indicates that no images were found in the '\/train' directory that match the allowed formats ('.bmp', '.gif', '.jpeg', '.jpg', '.png'), likely because the directory is empty or contains files of other formats; verify the directory's contents and ensure images are in the correct format and properly located."}
{"Error Text":"Exception The input image should np.float32 in the range [0, 1]","Alignment":"The `Exception` indicates that the input image must be a NumPy array of type `np.float32` and normalized within the range [0, 1], but it does not meet these conditions; convert and scale your image data accordingly before processing."}
{"Error Text":"ValueError Sample larger than population or is negative","Alignment":"The `ValueError` occurs when attempting to sample more items than are available in the population or using a negative sample size, often with functions like `random.sample`; ensure the sample size is positive and does not exceed the population size."}
{"Error Text":"TypeError Layer.__init__() takes 1 positional argument but 2 were given","Alignment":"The `TypeError` occurs because the `__init__()` method of a `Layer` class was called with two arguments, but it only accepts one; ensure that you are passing the correct number of arguments as specified in the class definition or library documentation."}
{"Error Text":"tensorflow.python.framework.errors_impl.NotFoundError Unsuccessful TensorSliceReader constructor: Failed to find any matching files for \/gru\/","Alignment":"The `NotFoundError` indicates that the `TensorSliceReader` failed to locate any files at the specified directory '\/gru', which is necessary for operations like restoring a TensorFlow model; verify the file path to ensure it is correct and that the required files exist in that location."}
{"Error Text":"ValueError Unknown loss function: 'perplexity_loss'. Please ensure you are using a `keras.utils.custom_object_scope` and that this object is included in the scope.","Alignment":"The `ValueError` indicates that the loss function 'perplexity_loss' is not recognized, likely because it is a custom loss function not included in the standard Keras library; to resolve this, define 'perplexity_loss' as a custom object and use it within a `keras.utils.custom_object_scope` or register it with Keras before using."}
{"Error Text":"ValueError Could not find matching concrete function to call loaded from the SavedModel","Alignment":"The `ValueError` suggests that TensorFlow was unable to locate a specific concrete function from a SavedModel that matches the provided call parameters; ensure that the function signatures match between what's being called and what's available in the SavedModel, adjusting input shapes, types, or names as needed."}
{"Error Text":"AttributeError __enter__","Alignment":"The `AttributeError` mentioning `__enter__` indicates that an object was used in a `with` statement but it does not support the context management protocol because it lacks an `__enter__` method; ensure the object is designed to be used with `with` or implement the `__enter__` and `__exit__` methods in the object's class to support context management."}
{"Error Text":"tensorflow.python.framework.errors_impl.InvalidArgumentError: Graph execution error: 2 root error(s) found.\n  (0) INVALID_ARGUMENT:  Specified a list with shape [1,512] from a tensor with shape [1,256]\n\t [[{{node lstm_model\/rnn\/TensorArrayUnstack\/TensorListFromTensor}}]]\n\t [[string_lookup_1\/Cast\/_38]]\n  (1) INVALID_ARGUMENT:  Specified a list with shape [1,512] from a tensor with shape [1,256]\n\t [[{{node lstm_model\/rnn\/TensorArrayUnstack\/TensorListFromTensor}}]]\n0 successful operations.\n0 derived errors ignored. [Op:__inference_generate_one_step_1013]","Alignment":"The `InvalidArgumentError` indicates a mismatch in tensor shapes where a tensor of shape [1,256] is being reshaped or reinterpreted as a shape [1,512], which is not valid due to incompatible sizes; check the model's architecture and ensure that tensor shapes align correctly through each layer."}
{"Error Text":"ValueError `handle` is not available outside the replica context or a `tf.distribute.Strategy.update()` call.","Alignment":"The `ValueError` indicates that the `handle` variable is being accessed in a context where TensorFlow's distribution strategy does not permit it, which usually means outside of a distributed replica's context or an `update()` call; ensure that your code that accesses `handle` is within the proper distributed scope."}
{"Error Text":"ValueError Please use `tf.keras.losses.Reduction.SUM` or `tf.keras.losses.Reduction.NONE` for loss reduction when losses are used with `tf.distribute.Strategy` outside of the built-in training loops. You can implement `tf.keras.losses.Reduction.SUM_OVER_BATCH_SIZE` using global batch size like:\n```\nwith strategy.scope():\n    loss_obj = tf.keras.losses.CategoricalCrossentropy(reduction=tf.keras.losses.Reduction.NONE)\n....\n    loss = tf.reduce_sum(loss_obj(labels, predictions)) * (1. \/ global_batch_size)\n```","Alignment":"The `ValueError` suggests that an incompatible loss reduction setting is being used with `tf.distribute.Strategy`, and recommends using either `tf.keras.losses.Reduction.SUM` or `tf.keras.losses.Reduction.NONE` instead, providing an example of how to manually implement `SUM_OVER_BATCH_SIZE` using the global batch size within the distributed strategy's scope."}
{"Error Text":"NotImplementedError:  Loading a dataset cached in a LocalFileSystem is not supported.","Alignment":"The `NotImplementedError` indicates that the operation to load a dataset cached in a LocalFileSystem is not currently supported by the library being used, suggesting you should check the library's documentation for supported storage systems or update the library if such support has been added in newer versions."}
{"Error Text":"AttributeError:  'DatasetDict' object has no attribute 'train_test_split'","Alignment":"The `AttributeError` occurs because the `DatasetDict` object does not have a `train_test_split` method; you may need to use the `train_test_split` function directly from the library or access individual datasets within the `DatasetDict` to apply splits."}
{"Error Text":"AttributeError:  'functools.partial' object has no attribute '__code__'","Alignment":"The `AttributeError` happens because a `functools.partial` object lacks a `__code__` attribute, which is necessary for operations that require inspecting the function's code, such as serialization or some forms of introspection; use the original function object instead for such operations."}
{"Error Text":"KeyError: \"Invalid key: 0. Please first select a split. For example: `my_dataset_dictionary['train'][0]`. Available splits: ['train']\"","Alignment":"The `KeyError` indicates that the dataset needs to be accessed by specifying a split before indexing, as in `my_dataset_dictionary['train'][0]`, because direct indexing without specifying a split like `my_dataset_dictionary[0]` is invalid for this `DatasetDict` structure."}
{"Error Text":"True is not defined","Alignment":"This error occurs because JavaScript is case-sensitive and recognizes true, not True; use the correct lowercase boolean value."}
{"Error Text":"Cannot read properties of undefined (reading 'toBe')","Alignment":"This error suggests you are trying to access the toBe method on an object that hasn't been properly initialized or defined, ensure the object or variable is correctly initialized before this operation."}
{"Error Text":"expect(...).notToBe is not a function","Alignment":"This  error happens because notToBe is not a valid method in the Jest testing framework; you should use not.toBe instead for negation checks in tests."}
{"Error Text":"expected \u2018;\u2019 before \u2018}\u2019 token [solution.c]","Alignment":"This error in C++ suggests a semicolon is missing in the syntax, usually before a closing brace that marks the end of a statement or a block."}
{"Error Text":"control reaches end of non-void function","Alignment":"This error means that a function expected to return a value does not have a return statement on all control paths, which is required to provide an output for each possible execution path."}
{"Error Text":"redeclaration of \u2018int count\u2019","Alignment":"This error occurs when the variable count is declared multiple times within the same scope, which is not allowed; ensure each variable is uniquely named within its scope."}
{"Error Text":"invalid types \u2018int[int]\u2019 for array subscript","Alignment":"This error happens when an integer is incorrectly used as an array index, possibly due to a type error or misuse of brackets; ensure indices are integers and the data structure is an array."}
{"Error Text":"expected identifier before numeric constant","Alignment":"This error typically occurs in C++ when a numeric constant is used where a variable name, function name, or other identifier is expected, often due to a misplaced token or syntax error."}
{"Error Text":"overloaded function with no contextual type information","Alignment":"This error means there are multiple functions with the same name but different parameters, and the compiler cannot determine which one to use without additional type information in the call."}
{"Error Text":"\u2018s\u2019 was not declared in this scope","Alignment":"This error indicates that the variable s is being used without being declared within the accessible scope; ensure all variables are declared before use."}
{"Error Text":"expected primary-expression before \u2018;\u2019 token","Alignment":"This error suggests that a valid expression is required before the semicolon in a statement, often indicating a syntax error or incomplete expression."}
{"Error Text":"expected unqualified-id before \u2018int\u2019","Alignment":"This error in C++ indicates that a type declaration like int appears in a place where the compiler expects an identifier, possibly due to a misplaced type specifier or syntax error."}
{"Error Text":"expected \u2018)\u2019 before \u2018;\u2019 token","Alignment":"This error suggests a closing parenthesis is missing in the code, likely causing a syntax error by prematurely ending a statement or expression."}
{"Error Text":"conflicting declaration \u2018int parts\u2019","Alignment":"This error occurs when the variable parts is declared with a type that conflicts with a previous declaration within the same scope, which can happen if it is first declared with a different type or if it's redeclared improperly."}
{"Error Text":"expected \u2018,\u2019 or \u2018;\u2019 before \u2018count\u2019","Alignment":"This error means a comma or semicolon was omitted before the declaration of count, likely causing a syntax error."}
{"Error Text":"expected \u2018}\u2019 at end of input","Alignment":"This error indicates that there is a missing closing brace '}' somewhere in the code, which is necessary to end a code block."}
{"Error Text":"\u2018parts\u2019 was not declared in this scope","Alignment":"This error occurs when the variable parts is used without being declared within the current or global scope."}
{"Error Text":"two or more data types in declaration of \u2018n\u2019","Alignment":"This error suggests conflicting types in the declaration of n, possibly due to a syntax error or incorrect variable declaration."}
{"Error Text":"declaration does not declare anything [-fpermissive]","Alignment":"This error happens when the compiler encounters a statement that seems to declare something but actually does not, possibly due to a syntax error."}
{"Error Text":"ISO C++ forbids comparison between pointer and integer [-fpermissive]","Alignment":"This error means there is an invalid comparison being made between a pointer and an integer, which is not allowed."}
{"Error Text":"expected \u2018)\u2019 before numeric constant","Alignment":"This error suggests a closing parenthesis is missing before a numeric constant in the code."}
{"Error Text":"no matching function for call to \u2018getline(std::istream&, double&)\u2019","Alignment":"This error indicates that there's an attempt to read input into a variable type that the getline function does not support."}
{"Error Text":"expected initializer before \u2018.\u2019 token","Alignment":"This error occurs when the code expects an initialization statement before a dot that is used for member access."}
{"Error Text":"expression list treated as compound expression in functional cast [-fpermissive]","Alignment":"This error suggests that a list of expressions is being misused in a place where a single compound expression is expected."}
{"Error Text":"invalid type argument of unary \u2018*\u2019 (have \u2018int\u2019)","Alignment":"This error occurs when dereferencing is attempted on something that is not a pointer type, in this case, an integer."}
{"Error Text":"no match for \u2018operator*\u2019 (operand type is \u2018std::__cxx11::basic_string<char>\u2019)","Alignment":"This error happens when trying to use the multiplication or dereference operator on types for which it is not defined, like std::string."}
{"Error Text":"\u2018cout\u2019 does not name a type","Alignment":"This error occurs when cout is mistakenly used as a type instead of an object of ostream."}
{"Error Text":"invalid use of template-name \u2018std::vector\u2019 without an argument list","Alignment":"This error means that a vector declaration is missing its type, like std::vector<int>."}
{"Error Text":"\u2018ln\u2019 declared as reference but not initialized","Alignment":"This error occurs because references in C++ must be initialized upon declaration."}
{"Error Text":"could not convert \u2018((void)0, s)\u2019 from \u2018std::__cxx11::string {aka std::__cxx11::basic_string<char>}\u2019 to \u2018bool\u2019","Alignment":"This error suggests an invalid conversion, likely from a comma operator sequence or a misuse of casting."}
{"Error Text":"invalid type argument of unary \u2018*\u2019 (have \u2018int\u2019)","Alignment":"The error occurs because the dereference operator '*' is used on an integer instead of a pointer, which is invalid because dereferencing applies to pointers to access their pointed-to value."}
{"Error Text":"ambiguous overload for \u2018operator=\u2019 (operand types are \u2018std::__cxx11::string {aka std::__cxx11::basic_string<char>}\u2019 and \u2018int\u2019)","Alignment":"\"Ambiguous overload for \u2018operator=\u2019\" error happens when the assignment operator is used with types that it can't handle, causing ambiguity."}
{"Error Text":"\u2018int getline\u2019 redeclared as different kind of symbol","Alignment":"This error indicates that getline was previously declared in a different context or with a different signature and is being incorrectly redeclared."}